Workbook

Sheet Summary
A1: Real Choices…Real Life — episode summary
A2: Every number below is a formula over the "All 99 episodes" sheet, so it updates if you change that sheet.
A4: Published episodes | B4: =COUNTA('All 99 episodes'!A2:A100) -> 99
A5: Distinct shows (not duplicates) | B5: =COUNTIF('All 99 episodes'!G2:G100,"No") -> 79
A6: Duplicates (red rows) | B6: =COUNTIF('All 99 episodes'!G2:G100,"Yes") -> 20
A7: Identical length (re-air) | B7: =COUNTIF('All 99 episodes'!I2:I100,"Identical*") -> 7
A8: 1:51 longer (same recording, new intro) | B8: =COUNTIF('All 99 episodes'!I2:I100,"1:51*") -> 10
A9: Different length (listen to check) | B9: =COUNTIF('All 99 episodes'!I2:I100,"Different*") -> 3
A10: Total running time, all 99 | B10: =SUM('All 99 episodes'!D2:D100) -> 3.0291204
A11: Running time, distinct shows only | B11: =SUMIF('All 99 episodes'!G2:G100,"No",'All 99 episodes'!D2:D100) -> 2.3990509
A12: Episodes already on YouTube as video | B12: =COUNTIF('All 99 episodes'!L2:L100,"Yes*") -> 8
A13: Distinct shows still to upload | B13: =B5-B12 -> 71 | C13: 71 if #65 and #77 are the same conversations as #1 and #4; 73 if they are separate recordings. Listen to check.
A14: Holistic Living | B14: =COUNTIFS('All 99 episodes'!E2:E100,A14,'All 99 episodes'!G2:G100,"No") -> 5 | C14: =COUNTIF('All 99 episodes'!E2:E100,A14) -> 6
A15: Spirituality | B15: =COUNTIFS('All 99 episodes'!E2:E100,A15,'All 99 episodes'!G2:G100,"No") -> 7 | C15: =COUNTIF('All 99 episodes'!E2:E100,A15) -> 8
A16: Health | B16: =COUNTIFS('All 99 episodes'!E2:E100,A16,'All 99 episodes'!G2:G100,"No") -> 11 | C16: =COUNTIF('All 99 episodes'!E2:E100,A16) -> 12
A17: Family & Relationships | B17: =COUNTIFS('All 99 episodes'!E2:E100,A17,'All 99 episodes'!G2:G100,"No") -> 20 | C17: =COUNTIF('All 99 episodes'!E2:E100,A17) -> 24
A18: Career & Purpose | B18: =COUNTIFS('All 99 episodes'!E2:E100,A18,'All 99 episodes'!G2:G100,"No") -> 14 | C18: =COUNTIF('All 99 episodes'!E2:E100,A18) -> 20
A19: Finances | B19: =COUNTIFS('All 99 episodes'!E2:E100,A19,'All 99 episodes'!G2:G100,"No") -> 11 | C19: =COUNTIF('All 99 episodes'!E2:E100,A19) -> 12
A20: Holidays & Year-End | B20: =COUNTIFS('All 99 episodes'!E2:E100,A20,'All 99 episodes'!G2:G100,"No") -> 8 | C20: =COUNTIF('All 99 episodes'!E2:E100,A20) -> 14
A21: About Abundance Legacy | B21: =COUNTIFS('All 99 episodes'!E2:E100,A21,'All 99 episodes'!G2:G100,"No") -> 3 | C21: =COUNTIF('All 99 episodes'!E2:E100,A21) -> 3
A22: Total | B22: =SUM(B14:B21) -> 79 | C22: =SUM(C14:C21) -> 99
A24: Source: the Real Choices…Real Life episode list on Buzzsprout (published Jan 5, 2022 – Jan 17, 2024). Duplicates were found by matching titles and exact running times.

Sheet All 99 episodes
A1: # | B1: Title | C1: Published | D1: Length | E1: Playlist | F1: On the episode | G1: Duplicate? | H1: Duplicate of # | I1: How it differs | J1: Notes | K1: Buzzsprout link | L1: Already on YouTube?
A2: 1 | B2: Holistic Living | C2: 44566 | D2: 0.025150463 | E2: Holistic Living | F2: Hosts only | G2: No | J2: Repeated later as #65; Pilot episode | K2: https://www.buzzsprout.com/1891053/episodes | L2: No
A3: 2 | B3: Discover Your Spirituality | C3: 44573 | D3: 0.024039352 | E3: Spirituality | F3: Hosts only | G3: No | K3: https://www.buzzsprout.com/1891053/episodes | L3: Yes, as video: "Discovering Your Spirituality" (34:45)
A4: 3 | B4: Health & Relationships | C4: 44580 | D4: 0.027326389 | E4: Health | F4: Hosts only | G4: No | K4: https://www.buzzsprout.com/1891053/episodes | L4: Yes, as video: "Health & Relationships" (39:32)
A5: 4 | B5: Is Your Career Your Passion? | C5: 44587 | D5: 0.024548611 | E5: Career & Purpose | F5: Hosts only | G5: No | J5: Repeated later as #77 | K5: https://www.buzzsprout.com/1891053/episodes | L5: No
A6: 5 | B6: Understanding Energy | C6: 44594 | D6: 0.036944444 | E6: Spirituality | F6: Cindy Tawiah | G6: No | K6: https://www.buzzsprout.com/1891053/episodes | L6: Yes, as video: "Understanding Energy 1" (53:13)
A7: 6 | B7: How to Live a Healthy Life | C7: 44601 | D7: 0.038321759 | E7: Health | F7: Steve Bowman (Live and Lead) | G7: No | K7: https://www.buzzsprout.com/1891053/episodes | L7: No
A8: 7 | B8: Do I Have the Right Relationships? | C8: 44608 | D8: 0.027824074 | E8: Family & Relationships | F8: Jessica Karin (co-host) | G8: No | K8: https://www.buzzsprout.com/1891053/episodes | L8: Yes, as video: "Do I Have The Right Relationship" (40:05)
A9: 8 | B9: Am I Doing What I Love? If Not Why Not? | C9: 44615 | D9: 0.038900463 | E9: Career & Purpose | F9: Jolisa Webb Dudley, life coach | G9: No | J9: Repeated later as #59 | K9: https://www.buzzsprout.com/1891053/episodes | L9: Yes, as video: "Am I doing what I love, if not why not" (56:02)
A10: 9 | B10: Know Your Numbers | C10: 44622 | D10: 0.02587963 | E10: Finances | F10: Nathaniel X. Ross | G10: No | J10: Pilot episode | K10: https://www.buzzsprout.com/1891053/episodes | L10: No
A11: 10 | B11: Understanding Energy Work | C11: 44629 | D11: 0.037361111 | E11: Spirituality | F11: Terri Pippin | G11: No | K11: https://www.buzzsprout.com/1891053/episodes | L11: No
A12: 11 | B12: The Importance of Sleep | C12: 44636 | D12: 0.029016204 | E12: Health | F12: Steve Bowman (Live and Lead) | G12: No | K12: https://www.buzzsprout.com/1891053/episodes | L12: No
A13: 12 | B13: Cleaning Up Your Inner Circle | C13: 44643 | D13: 0.029537037 | E13: Family & Relationships | F13: Jessica Karin (co-host) | G13: No | J13: Repeated later as #63 | K13: https://www.buzzsprout.com/1891053/episodes | L13: Yes, as video: "Cleaning up your inner circle" (42:33)
A14: 13 | B14: How to Overcome Mistakes in the Workplace | C14: 44650 | D14: 0.03755787 | E14: Career & Purpose | F14: Jolisa Webb Dudley, life coach | G14: No | J14: Repeated later as #64 | K14: https://www.buzzsprout.com/1891053/episodes | L14: No
A15: 14 | B15: Hiring the Right Financial Planner | C15: 44664 | D15: 0.030601852 | E15: Finances | F15: Nathaniel X. Ross | G15: No | K15: https://www.buzzsprout.com/1891053/episodes | L15: No
A16: 15 | B16: What is an Intuitive Session? | C16: 44671 | D16: 0.023229167 | E16: Spirituality | F16: Hosts only | G16: No | K16: https://www.buzzsprout.com/1891053/episodes | L16: No
A17: 16 | B17: Eating Well | C17: 44678 | D17: 0.026574074 | E17: Health | F17: Steve Bowman (Live and Lead) | G17: No | K17: https://www.buzzsprout.com/1891053/episodes | L17: No
A18: 17 | B18: Divorce Cues Are You Listening? | C18: 44699 | D18: 0.032893519 | E18: Family & Relationships | F18: Jolisa Webb Dudley, divorce coach | G18: No | J18: Repeated later as #68 | K18: https://www.buzzsprout.com/1891053/episodes | L18: No
A19: 18 | B19: Understanding Your Credit | C19: 44713 | D19: 0.023449074 | E19: Finances | F19: Stephanie Jackson | G19: No | K19: https://www.buzzsprout.com/1891053/episodes | L19: No
A20: 19 | B20: Why Is It Important to have a Mentor? | C20: 44720 | D20: 0.029085648 | E20: Career & Purpose | F20: Greg Moses | G20: No | K20: https://www.buzzsprout.com/1891053/episodes | L20: No
A21: 20 | B21: A Spiritual Discussion with Terri Pippin | C21: 44727 | D21: 0.039166667 | E21: Spirituality | F21: Terri Pippin | G21: No | K21: https://www.buzzsprout.com/1891053/episodes | L21: No
A22: 21 | B22: Do you have a healthy relationship with yourself? | C22: 44762 | D22: 0.026168981 | E22: Family & Relationships | F22: Jessica Karin (co-host) | G22: No | K22: https://www.buzzsprout.com/1891053/episodes | L22: No
A23: 22 | B23: The Importance of Budgeting | C23: 44769 | D23: 0.033240741 | E23: Finances | F23: Nathaniel X. Ross | G23: No | K23: https://www.buzzsprout.com/1891053/episodes | L23: No
A24: 23 | B24: What is dating today? | C24: 44776 | D24: 0.033229167 | E24: Family & Relationships | F24: Jessica Karin (co-host) | G24: No | K24: https://www.buzzsprout.com/1891053/episodes | L24: No
A25: 24 | B25: The three components to finances | C25: 44783 | D25: 0.028564815 | E25: Finances | F25: Nathaniel X. Ross | G25: No | K25: https://www.buzzsprout.com/1891053/episodes | L25: No
A26: 25 | B26: How the family can support during divorce | C26: 44790 | D26: 0.034652778 | E26: Family & Relationships | F26: Jolisa Webb Dudley (per the production schedule) | G26: No | K26: https://www.buzzsprout.com/1891053/episodes | L26: No
A27: 26 | B27: Divorce and Children | C27: 44797 | D27: 0.04025463 | E27: Family & Relationships | F27: Not listed | G27: No | K27: https://www.buzzsprout.com/1891053/episodes | L27: No
A28: 27 | B28: Soul Care | C28: 44804 | D28: 0.036863426 | E28: Spirituality | F28: Stacy Y. Gibson | G28: No | J28: Repeated later as #71 | K28: https://www.buzzsprout.com/1891053/episodes | L28: No
A29: 28 | B29: Taking Time to Heal Between Relationships | C29: 44811 | D29: 0.029976852 | E29: Family & Relationships | F29: Jessica Karin (co-host) | G29: No | K29: https://www.buzzsprout.com/1891053/episodes | L29: No
A30: 29 | B30: Avoiding Risky Substances | C30: 44818 | D30: 0.029664352 | E30: Health | F30: Steve Bowman (Live and Lead) | G30: No | K30: https://www.buzzsprout.com/1891053/episodes | L30: No
A31: 30 | B31: Real Estate | C31: 44825 | D31: 0.042685185 | E31: Finances | F31: Hakiim Herring (The Herring Group) | G31: No | K31: https://www.buzzsprout.com/1891053/episodes | L31: No
A32: 31 | B32: Cultivating Relationships | C32: 44832 | D32: 0.029016204 | E32: Family & Relationships | F32: Steve Bowman (Live and Lead) | G32: No | K32: https://www.buzzsprout.com/1891053/episodes | L32: No
A33: 32 | B33: The Importance of Forgiving Yourself for Relational Failures | C33: 44839 | D33: 0.030439815 | E33: Family & Relationships | F33: Jessica Karin (co-host) | G33: No | K33: https://www.buzzsprout.com/1891053/episodes | L33: No
A34: 33 | B34: Young Black Entrepreneurship | C34: 44846 | D34: 0.037824074 | E34: Career & Purpose | F34: Hakiim Herring (The Herring Group) | G34: No | K34: https://www.buzzsprout.com/1891053/episodes | L34: No
A35: 34 | B35: A Journey Through One's Career | C35: 44853 | D35: 0.031076389 | E35: Career & Purpose | F35: Amaris Leon | G35: No | K35: https://www.buzzsprout.com/1891053/episodes | L35: No
A36: 35 | B36: Dating at Different Ages and Stages | C36: 44860 | D36: 0.023599537 | E36: Family & Relationships | F36: Jessica Karin (co-host) | G36: No | K36: https://www.buzzsprout.com/1891053/episodes | L36: No
A37: 36 | B37: Community Involvement | C37: 44867 | D37: 0.027800926 | E37: Holistic Living | F37: Amaris Leon | G37: No | K37: https://www.buzzsprout.com/1891053/episodes | L37: No
A38: 37 | B38: How do I become a life coach? | C38: 44874 | D38: 0.032511574 | E38: Career & Purpose | F38: Nathaniel X. Ross | G38: No | K38: https://www.buzzsprout.com/1891053/episodes | L38: No
A39: 38 | B39: How do I leave a legacy for my family? | C39: 44881 | D39: 0.0265625 | E39: Finances | F39: Nathaniel X. Ross | G39: No | K39: https://www.buzzsprout.com/1891053/episodes | L39: No
A40: 39 | B40: Thanksgiving | C40: 44888 | D40: 0.035208333 | E40: Holidays & Year-End | F40: Hosts only | G40: No | J40: Repeated later as #88 | K40: https://www.buzzsprout.com/1891053/episodes | L40: No
...

Sheet 30-day plan
A1: 30-day relaunch plan
A2: Start date | B2: 46300 | C2: ← Change this yellow cell and every date below moves with it.
A4: Day | B4: Date | C4: Focus | D4: What to do | E4: Episodes (#, title) | F4: Done?
A5: 1 | B5: =$B$2+A5-1 -> 46300 | C5: Before snapshot | D5: Screen-record the channel. Save views, watch time and subscribers from YouTube Studio → Analytics. Fix or delete the broken playlist.
A6: 2 | B6: =$B$2+A6-1 -> 46301 | C6: Set up | D6: Create the 8 playlists. Write the description template (what you'll learn, who's on it, one link, rights line, hashtags). Send Nate the 7 questions.
A7: 3 | B7: =$B$2+A7-1 -> 46302 | C7: Pilot, part 1 | D7: Play the first minute of each pilot file to confirm the copy. Write titles, descriptions, thumbnails. | E7: #1 Holistic Living; #9 Know Your Numbers; #44 Year End Wrap Part Two; #46 Being a Health Advocate; #74 Finance 2023
A8: 4 | B8: =$B$2+A8-1 -> 46303 | C8: Pilot, part 2 | D8: Upload the 5 pilot episodes to their playlists. Cut 2–3 shorts from each and schedule them. | E8: Same 5 as day 3
A9: 5 | B9: =$B$2+A9-1 -> 46304 | C9: Upload: Holistic Living | D9: Upload these, add to their playlist, cut 2–3 shorts each. Keep repeats off YouTube. | E9: #36 Community Involvement; #47 New Beginnings for 2023; #72 Holistic Education
A10: 6 | B10: =$B$2+A10-1 -> 46305 | C10: Upload: Finances, Holistic Living | D10: Upload these, add to their playlist, cut 2–3 shorts each. Keep repeats off YouTube. | E10: #73 How Do You Handle Death?; #14 Hiring the Right Financial Planner; #18 Understanding Your Credit
A11: 7 | B11: =$B$2+A11-1 -> 46306 | C11: Upload: Finances | D11: Upload these, add to their playlist, cut 2–3 shorts each. Keep repeats off YouTube. | E11: #22 The Importance of Budgeting; #24 The three components to finances; #30 Real Estate
A12: 8 | B12: =$B$2+A12-1 -> 46307 | C12: Upload: Finances | D12: Upload these, add to their playlist, cut 2–3 shorts each. Keep repeats off YouTube. | E12: #38 How do I leave a legacy for my family?; #53 Finances 2023; #85 How Your Finances Impact Your Life
A13: 9 | B13: =$B$2+A13-1 -> 46308 | C13: Upload: Finances, Spirituality | D13: Upload these, add to their playlist, cut 2–3 shorts each. Keep repeats off YouTube. | E13: #90 Investments; #2 Discover Your Spirituality; #5 Understanding Energy
A14: 10 | B14: =$B$2+A14-1 -> 46309 | C14: Upload: Spirituality | D14: Upload these, add to their playlist, cut 2–3 shorts each. Keep repeats off YouTube. | E14: #10 Understanding Energy Work; #15 What is an Intuitive Session?; #20 A Spiritual Discussion with Terri Pippin
A15: 11 | B15: =$B$2+A15-1 -> 46310 | C15: Upload: Career & Purpose, Spirituality | D15: Upload these, add to their playlist, cut 2–3 shorts each. Keep repeats off YouTube. | E15: #27 Soul Care; #49 Spirituality; #4 Is Your Career Your Passion?
A16: 12 | B16: =$B$2+A16-1 -> 46311 | C16: Upload: Career & Purpose | D16: Upload these, add to their playlist, cut 2–3 shorts each. Keep repeats off YouTube. | E16: #8 Am I Doing What I Love? If Not Why Not?; #13 How to Overcome Mistakes in the Workplace; #19 Why Is It Important to have a Mentor?
A17: 13 | B17: =$B$2+A17-1 -> 46312 | C17: Upload: Career & Purpose | D17: Upload these, add to their playlist, cut 2–3 shorts each. Keep repeats off YouTube. | E17: #33 Young Black Entrepreneurship; #34 A Journey Through One's Career; #37 How do I become a life coach?
A18: 14 | B18: =$B$2+A18-1 -> 46313 | C18: Upload: Career & Purpose | D18: Upload these, add to their playlist, cut 2–3 shorts each. Keep repeats off YouTube. | E18: #41 Being A Podcast Host; #52 Career 2023; #56 Coaching - Part 1
... A33: 29 | B33: =$B$2+A33-1 -> 46328 | C33: Upload: About Abundance Legacy | D33: Upload these, add to their playlist, cut 2–3 shorts each. Keep repeats off YouTube. | E33: #54 ABL Services - Part One; #55 ABL Services - Part Two
A34: 30 | B34: =$B$2+A34-1 -> 46329 | C34: Review | D34: Compare this week's numbers with the Day 1 snapshot. Send Nate the before-and-after.
A36: Days 5–29 cover the other 74 distinct shows, 3 a day. Blue-shaded rows are the pilot.

Sheet YouTube videos (fill in)
A1: Compare the YouTube channel with the 99 episodes
A2: Rows 5–20 were read from the channel’s Videos tab on Sept 30, 2026. Add the ~51 "It’s Your Life OWN It" videos below them (YouTube Studio → Content lists every title). Column D matches a podcast episode automatically when the title is identical.
A4: YouTube title | B4: Link or length | C4: Views | D4: Matching episode # | E4: Duplicate on YouTube? | F4: Playlist it belongs in | G4: Notes | H4: Type
A5: Health & Relationships | B5: Length 39:32 | C5: 6 | D5: 3 | E5: =IF(A5="","",IF(COUNTIF($A$5:$A$79,A5)>1,"Yes — appears "&COUNTIF($A$5:$A$79,A5)&" times","No")) -> No | F5: Health | G5: Podcast #3 on video; length matches. Retitle, describe, add to playlist. | H5: Podcast episode (video)
A6: Discovering Your Spirituality | B6: Length 34:45 | C6: 4 | D6: 2 | E6: =IF(A6="","",IF(COUNTIF($A$5:$A$79,A6)>1,"Yes — appears "&COUNTIF($A$5:$A$79,A6)&" times","No")) -> No | F6: Spirituality | G6: Podcast #2 on video; length matches. Retitle, describe, add to playlist. | H6: Podcast episode (video)
A7: Understanding Energy 1 | B7: Length 53:13 | C7: 5 | D7: 5 | E7: =IF(A7="","",IF(COUNTIF($A$5:$A$79,A7)>1,"Yes — appears "&COUNTIF($A$5:$A$79,A7)&" times","No")) -> No | F7: Spirituality | G7: Podcast #5 on video; length matches. Retitle, describe, add to playlist. | H7: Podcast episode (video)
A8: Am I doing what I love, if not why not | B8: Length 56:02 | C8: 1 | D8: 8 | E8: =IF(A8="","",IF(COUNTIF($A$5:$A$79,A8)>1,"Yes — appears "&COUNTIF($A$5:$A$79,A8)&" times","No")) -> No | F8: Career & Purpose | G8: Podcast #8 on video; length matches. Retitle, describe, add to playlist. | H8: Podcast episode (video)
A9: Do I Have The Right Relationship | B9: Length 40:05 | C9: 7 | D9: 7 | E9: =IF(A9="","",IF(COUNTIF($A$5:$A$79,A9)>1,"Yes — appears "&COUNTIF($A$5:$A$79,A9)&" times","No")) -> No | F9: Family & Relationships | G9: Podcast #7 on video; length matches. Retitle, describe, add to playlist. | H9: Podcast episode (video)
A10: Holistic Living | B10: Length 37:03 | C10: 1 | D10: 65 | E10: =IF(A10="","",IF(COUNTIF($A$5:$A$79,A10)>1,"Yes — appears "&COUNTIF($A$5:$A$79,A10)&" times","No")) -> No | F10: Holistic Living | G10: Podcast #65 on video; length matches. Retitle, describe, add to playlist. | H10: Podcast episode (video)
A11: Is Your Career Your Passion | B11: Length 38:07 | C11: 2 | D11: 77 | E11: =IF(A11="","",IF(COUNTIF($A$5:$A$79,A11)>1,"Yes — appears "&COUNTIF($A$5:$A$79,A11)&" times","No")) -> No | F11: Career & Purpose | G11: Podcast #77 on video; length matches. Retitle, describe, add to playlist. | H11: Podcast episode (video)
A12: Cleaning up your inner circle | B12: Length 42:33 | C12: 14 | D12: 12 | E12: =IF(A12="","",IF(COUNTIF($A$5:$A$79,A12)>1,"Yes — appears "&COUNTIF($A$5:$A$79,A12)&" times","No")) -> No | F12: Family & Relationships | G12: Podcast #12 on video; length matches. Retitle, describe, add to playlist. | H12: Podcast episode (video)
A13: Real Choices Real Life Podcast Commercial | B13: Length 0:55 | C13: 8 | D13: Promo — not an episode | E13: =IF(A13="","",IF(COUNTIF($A$5:$A$79,A13)>1,"Yes — appears "&COUNTIF($A$5:$A$79,A13)&" times","No")) -> No | F13: About Abundance Legacy | G13: Short promo | H13: Promo
A14: Women Group Commercial | B14: Length 0:54 | C14: 5 | D14: Promo — not an episode | E14: =IF(A14="","",IF(COUNTIF($A$5:$A$79,A14)>1,"Yes — appears "&COUNTIF($A$5:$A$79,A14)&" times","No")) -> No | F14: About Abundance Legacy | G14: Short promo | H14: Promo
A15: Men’s Group Commercial | B15: Length 0:56 | C15: 9 | D15: Promo — not an episode | E15: =IF(A15="","",IF(COUNTIF($A$5:$A$79,A15)>1,"Yes — appears "&COUNTIF($A$5:$A$79,A15)&" times","No")) -> No | F15: About Abundance Legacy | G15: Short promo | H15: Promo
A16: Hump Revised Video 2 | B16: Length 0:56 | C16: 4 | D16: Promo — not an episode | E16: =IF(A16="","",IF(COUNTIF($A$5:$A$79,A16)>1,"Yes — appears "&COUNTIF($A$5:$A$79,A16)&" times","No")) -> No | F16: About Abundance Legacy | G16: Short promo | H16: Promo
A17: Donation Video | B17: Length 0:55 | C17: 19 | D17: Promo — not an episode | E17: =IF(A17="","",IF(COUNTIF($A$5:$A$79,A17)>1,"Yes — appears "&COUNTIF($A$5:$A$79,A17)&" times","No")) -> No | F17: About Abundance Legacy | G17: Short promo | H17: Promo
A18: Article Video | B18: Length 0:54 | C18: 0 | D18: Promo — not an episode | E18: =IF(A18="","",IF(COUNTIF($A$5:$A$79,A18)>1,"Yes — appears "&COUNTIF($A$5:$A$79,A18)&" times","No")) -> No | F18: About Abundance Legacy | G18: Short promo | H18: Promo
A19: Financial Boot Camp Commercial | B19: Length 1:40 | C19: 1 | D19: Promo — not an episode | E19: =IF(A19="","",IF(COUNTIF($A$5:$A$79,A19)>1,"Yes — appears "&COUNTIF($A$5:$A$79,A19)&" times","No")) -> No | F19: About Abundance Legacy | G19: Short promo | H19: Promo
A20: Choice Video | B20: Length 1:40 | C20: 2 | D20: Promo — not an episode | E20: =IF(A20="","",IF(COUNTIF($A$5:$A$79,A20)>1,"Yes — appears "&COUNTIF($A$5:$A$79,A20)&" times","No")) -> No | F20: About Abundance Legacy | G20: Short promo | H20: Promo
D21: =IFERROR(INDEX('All 99 episodes'!$A$2:$A$100,MATCH(A21,'All 99 episodes'!$B$2:$B$100,0)),IF(A21="","","No exact match — check by hand")) | E21: =IF(A21="","",IF(COUNTIF($A$5:$A$79,A21)>1,"Yes — appears "&COUNTIF($A$5:$A$79,A21)&" times","No")) | F21: =IFERROR(INDEX('All 99 episodes'!$E$2:$E$100,MATCH(A21,'All 99 episodes'!$B$2:$B$100,0)),"")
D22: =IFERROR(INDEX('All 99 episodes'!$A$2:$A$100,MATCH(A22,'All 99 episodes'!$B$2:$B$100,0)),IF(A22="","","No exact match — check by hand")) | E22: =IF(A22="","",IF(COUNTIF($A$5:$A$79,A22)>1,"Yes — appears "&COUNTIF($A$5:$A$79,A22)&" times","No")) | F22: =IFERROR(INDEX('All 99 episodes'!$E$2:$E$100,MATCH(A22,'All 99 episodes'!$B$2:$B$100,0)),"")
D23: =IFERROR(INDEX('All 99 episodes'!$A$2:$A$100,MATCH(A23,'All 99 episodes'!$B$2:$B$100,0)),IF(A23="","","No exact match — check by hand")) | E23: =IF(A23="","",IF(COUNTIF($A$5:$A$79,A23)>1,"Yes — appears "&COUNTIF($A$5:$A$79,A23)&" times","No")) | F23: =IFERROR(INDEX('All 99 episodes'!$E$2:$E$100,MATCH(A23,'All 99 episodes'!$B$2:$B$100,0)),"")
D24: =IFERROR(INDEX('All 99 episodes'!$A$2:$A$100,MATCH(A24,'All 99 episodes'!$B$2:$B$100,0)),IF(A24="","","No exact match — check by hand")) | E24: =IF(A24="","",IF(COUNTIF($A$5:$A$79,A24)>1,"Yes — appears "&COUNTIF($A$5:$A$79,A24)&" times","No")) | F24: =IFERROR(INDEX('All 99 episodes'!$E$2:$E$100,MATCH(A24,'All 99 episodes'!$B$2:$B$100,0)),"")
D25: =IFERROR(INDEX('All 99 episodes'!$A$2:$A$100,MATCH(A25,'All 99 episodes'!$B$2:$B$100,0)),IF(A25="","","No exact match — check by hand")) | E25: =IF(A25="","",IF(COUNTIF($A$5:$A$79,A25)>1,"Yes — appears "&COUNTIF($A$5:$A$79,A25)&" times","No")) | F25: =IFERROR(INDEX('All 99 episodes'!$E$2:$E$100,MATCH(A25,'All 99 episodes'!$B$2:$B$100,0)),"")
D26: =IFERROR(INDEX('All 99 episodes'!$A$2:$A$100,MATCH(A26,'All 99 episodes'!$B$2:$B$100,0)),IF(A26="","","No exact match — check by hand")) | E26: =IF(A26="","",IF(COUNTIF($A$5:$A$79,A26)>1,"Yes — appears "&COUNTIF($A$5:$A$79,A26)&" times","No")) | F26: =IFERROR(INDEX('All 99 episodes'!$E$2:$E$100,MATCH(A26,'All 99 episodes'!$B$2:$B$100,0)),"")
D27: =IFERROR(INDEX('All 99 episodes'!$A$2:$A$100,MATCH(A27,'All 99 episodes'!$B$2:$B$100,0)),IF(A27="","","No exact match — check by hand")) | E27: =IF(A27="","",IF(COUNTIF($A$5:$A$79,A27)>1,"Yes — appears "&COUNTIF($A$5:$A$79,A27)&" times","No")) | F27: =IFERROR(INDEX('All 99 episodes'!$E$2:$E$100,MATCH(A27,'All 99 episodes'!$B$2:$B$100,0)),"")
D28: =IFERROR(INDEX('All 99 episodes'!$A$2:$A$100,MATCH(A28,'All 99 episodes'!$B$2:$B$100,0)),IF(A28="","","No exact match — check by hand")) | E28: =IF(A28="","",IF(COUNTIF($A$5:$A$79,A28)>1,"Yes — appears "&COUNTIF($A$5:$A$79,A28)&" times","No")) | F28: =IFERROR(INDEX('All 99 episodes'!$E$2:$E$100,MATCH(A28,'All 99 episodes'!$B$2:$B$100,0)),"")
D29: =IFERROR(INDEX('All 99 episodes'!$A$2:$A$100,MATCH(A29,'All 99 episodes'!$B$2:$B$100,0)),IF(A29="","","No exact match — check by hand")) | E29: =IF(A29="","",IF(COUNTIF($A$5:$A$79,A29)>1,"Yes — appears "&COUNTIF($A$5:$A$79,A29)&" times","No")) | F29: =IFERROR(INDEX('All 99 episodes'!$E$2:$E$100,MATCH(A29,'All 99 episodes'!$B$2:$B$100,0)),"")
D30: =IFERROR(INDEX('All 99 episodes'!$A$2:$A$100,MATCH(A30,'All 99 episodes'!$B$2:$B$100,0)),IF(A30="","","No exact match — check by hand")) | E30: =IF(A30="","",IF(COUNTIF($A$5:$A$79,A30)>1,"Yes — appears "&COUNTIF($A$5:$A$79,A30)&" times","No")) | F30: =IFERROR(INDEX('All 99 episodes'!$E$2:$E$100,MATCH(A30,'All 99 episodes'!$B$2:$B$100,0)),"")
D31: =IFERROR(INDEX('All 99 episodes'!$A$2:$A$100,MATCH(A31,'All 99 episodes'!$B$2:$B$100,0)),IF(A31="","","No exact match — check by hand")) | E31: =IF(A31="","",IF(COUNTIF($A$5:$A$79,A31)>1,"Yes — appears "&COUNTIF($A$5:$A$79,A31)&" times","No")) | F31: =IFERROR(INDEX('All 99 episodes'!$E$2:$E$100,MATCH(A31,'All 99 episodes'!$B$2:$B$100,0)),"")
D32: =IFERROR(INDEX('All 99 episodes'!$A$2:$A$100,MATCH(A32,'All 99 episodes'!$B$2:$B$100,0)),IF(A32="","","No exact match — check by hand")) | E32: =IF(A32="","",IF(COUNTIF($A$5:$A$79,A32)>1,"Yes — appears "&COUNTIF($A$5:$A$79,A32)&" times","No")) | F32: =IFERROR(INDEX('All 99 episodes'!$E$2:$E$100,MATCH(A32,'All 99 episodes'!$B$2:$B$100,0)),"")
... D79: =IFERROR(INDEX('All 99 episodes'!$A$2:$A$100,MATCH(A79,'All 99 episodes'!$B$2:$B$100,0)),IF(A79="","","No exact match — check by hand")) | E79: =IF(A79="","",IF(COUNTIF($A$5:$A$79,A79)>1,"Yes — appears "&COUNTIF($A$5:$A$79,A79)&" times","No")) | F79: =IFERROR(INDEX('All 99 episodes'!$E$2:$E$100,MATCH(A79,'All 99 episodes'!$B$2:$B$100,0)),"")
